<?xml version="1.0" encoding="UTF-8"?>
<testng-results ignored="0" total="5" passed="2" failed="2" skipped="1">
  <reporter-output>
  </reporter-output>
  <suite started-at="2024-09-09T23:59:14 IST" name="Suite" finished-at="2024-09-09T23:59:23 IST" duration-ms="9183">
    <groups>
    </groups>
    <test started-at="2024-09-09T23:59:14 IST" name="Test" finished-at="2024-09-09T23:59:23 IST" duration-ms="9183">
      <class name="Listener.TestClass">
        <test-method signature="Screenshot()[pri:0, instance:Listener.TestClass@6379eb]" started-at="2024-09-09T23:59:14 IST" name="Screenshot" finished-at="2024-09-09T23:59:23 IST" duration-ms="8925" status="PASS">
          <reporter-output>
          </reporter-output>
        </test-method> <!-- Screenshot -->
        <test-method signature="Test1()[pri:1, instance:Listener.TestClass@6379eb]" started-at="2024-09-09T23:59:23 IST" name="Test1" finished-at="2024-09-09T23:59:23 IST" duration-ms="6" status="PASS">
          <reporter-output>
          </reporter-output>
        </test-method> <!-- Test1 -->
        <test-method signature="Test2()[pri:2, instance:Listener.TestClass@6379eb]" started-at="2024-09-09T23:59:23 IST" name="Test2" finished-at="2024-09-09T23:59:23 IST" duration-ms="14" status="FAIL">
          <exception class="java.lang.AssertionError">
            <message>
              <![CDATA[expected [true] but found [false]]]>
            </message>
            <full-stacktrace>
              <![CDATA[java.lang.AssertionError: expected [true] but found [false]
at org.testng.Assert.fail(Assert.java:110)
at org.testng.Assert.failNotEquals(Assert.java:1413)
at org.testng.Assert.assertTrue(Assert.java:56)
at org.testng.Assert.assertTrue(Assert.java:66)
at Listener.TestClass.Test2(TestClass.java:33)
at java.base/jdk.internal.reflect.DirectMethodHandleAccessor.invoke(DirectMethodHandleAccessor.java:103)
at java.base/java.lang.reflect.Method.invoke(Method.java:580)
at org.testng.internal.invokers.MethodInvocationHelper.invokeMethod(MethodInvocationHelper.java:136)
at org.testng.internal.invokers.TestInvoker.invokeMethod(TestInvoker.java:658)
at org.testng.internal.invokers.TestInvoker.invokeTestMethod(TestInvoker.java:219)
at org.testng.internal.invokers.MethodRunner.runInSequence(MethodRunner.java:50)
at org.testng.internal.invokers.TestInvoker$MethodInvocationAgent.invoke(TestInvoker.java:923)
at org.testng.internal.invokers.TestInvoker.invokeTestMethods(TestInvoker.java:192)
at org.testng.internal.invokers.TestMethodWorker.invokeTestMethods(TestMethodWorker.java:146)
at org.testng.internal.invokers.TestMethodWorker.run(TestMethodWorker.java:128)
at java.base/java.util.ArrayList.forEach(ArrayList.java:1596)
at org.testng.TestRunner.privateRun(TestRunner.java:808)
at org.testng.TestRunner.run(TestRunner.java:603)
at org.testng.SuiteRunner.runTest(SuiteRunner.java:429)
at org.testng.SuiteRunner.runSequentially(SuiteRunner.java:423)
at org.testng.SuiteRunner.privateRun(SuiteRunner.java:383)
at org.testng.SuiteRunner.run(SuiteRunner.java:326)
at org.testng.SuiteRunnerWorker.runSuite(SuiteRunnerWorker.java:52)
at org.testng.SuiteRunnerWorker.run(SuiteRunnerWorker.java:95)
at org.testng.TestNG.runSuitesSequentially(TestNG.java:1249)
at org.testng.TestNG.runSuitesLocally(TestNG.java:1169)
at org.testng.TestNG.runSuites(TestNG.java:1092)
at org.testng.TestNG.run(TestNG.java:1060)
at org.testng.remote.AbstractRemoteTestNG.run(AbstractRemoteTestNG.java:115)
at org.testng.remote.RemoteTestNG.initAndRun(RemoteTestNG.java:293)
at org.testng.remote.RemoteTestNG.main(RemoteTestNG.java:91)
]]>
            </full-stacktrace>
          </exception> <!-- java.lang.AssertionError -->
          <reporter-output>
          </reporter-output>
        </test-method> <!-- Test2 -->
        <test-method signature="Test3()[pri:3, instance:Listener.TestClass@6379eb]" started-at="2024-09-09T23:59:23 IST" name="Test3" finished-at="2024-09-09T23:59:23 IST" duration-ms="119" status="FAIL">
          <exception class="org.testng.internal.thread.ThreadTimeoutException">
            <message>
              <![CDATA[Method Listener.TestClass.Test3() didn't finish within the time-out 100]]>
            </message>
            <full-stacktrace>
              <![CDATA[org.testng.internal.thread.ThreadTimeoutException: Method Listener.TestClass.Test3() didn't finish within the time-out 100
at java.base/java.lang.Thread.sleep0(Native Method)
at java.base/java.lang.Thread.sleep(Thread.java:509)
at Listener.TestClass.Test3(TestClass.java:39)
at java.base/jdk.internal.reflect.DirectMethodHandleAccessor.invoke(DirectMethodHandleAccessor.java:103)
at java.base/java.lang.reflect.Method.invoke(Method.java:580)
at org.testng.internal.invokers.MethodInvocationHelper.invokeMethod(MethodInvocationHelper.java:136)
at org.testng.internal.invokers.InvokeMethodRunnable.runOne(InvokeMethodRunnable.java:44)
at org.testng.internal.invokers.InvokeMethodRunnable.call(InvokeMethodRunnable.java:72)
at org.testng.internal.invokers.InvokeMethodRunnable.call(InvokeMethodRunnable.java:10)
at java.base/java.util.concurrent.FutureTask.run(FutureTask.java:317)
at java.base/java.util.concurrent.ThreadPoolExecutor.runWorker(ThreadPoolExecutor.java:1144)
at java.base/java.util.concurrent.ThreadPoolExecutor$Worker.run(ThreadPoolExecutor.java:642)
at java.base/java.lang.Thread.run(Thread.java:1583)
]]>
            </full-stacktrace>
          </exception> <!-- org.testng.internal.thread.ThreadTimeoutException -->
          <reporter-output>
          </reporter-output>
        </test-method> <!-- Test3 -->
        <test-method signature="Test4()[pri:4, instance:Listener.TestClass@6379eb]" started-at="2024-09-09T23:59:23 IST" name="Test4" finished-at="2024-09-09T23:59:23 IST" depends-on-methods="Listener.TestClass.Test3" duration-ms="1" status="SKIP">
          <exception class="java.lang.Throwable">
            <message>
              <![CDATA[Method TestClass.Test4()[pri:4, instance:Listener.TestClass@6379eb] depends on not successfully finished methods]]>
            </message>
            <full-stacktrace>
              <![CDATA[java.lang.Throwable: Method TestClass.Test4()[pri:4, instance:Listener.TestClass@6379eb] depends on not successfully finished methods
at org.testng.internal.invokers.TestInvoker.invokeTestMethods(TestInvoker.java:148)
at org.testng.internal.invokers.TestMethodWorker.invokeTestMethods(TestMethodWorker.java:146)
at org.testng.internal.invokers.TestMethodWorker.run(TestMethodWorker.java:128)
at java.base/java.util.ArrayList.forEach(ArrayList.java:1596)
at org.testng.TestRunner.privateRun(TestRunner.java:808)
at org.testng.TestRunner.run(TestRunner.java:603)
at org.testng.SuiteRunner.runTest(SuiteRunner.java:429)
at org.testng.SuiteRunner.runSequentially(SuiteRunner.java:423)
at org.testng.SuiteRunner.privateRun(SuiteRunner.java:383)
at org.testng.SuiteRunner.run(SuiteRunner.java:326)
at org.testng.SuiteRunnerWorker.runSuite(SuiteRunnerWorker.java:52)
at org.testng.SuiteRunnerWorker.run(SuiteRunnerWorker.java:95)
at org.testng.TestNG.runSuitesSequentially(TestNG.java:1249)
at org.testng.TestNG.runSuitesLocally(TestNG.java:1169)
at org.testng.TestNG.runSuites(TestNG.java:1092)
at org.testng.TestNG.run(TestNG.java:1060)
at org.testng.remote.AbstractRemoteTestNG.run(AbstractRemoteTestNG.java:115)
at org.testng.remote.RemoteTestNG.initAndRun(RemoteTestNG.java:293)
at org.testng.remote.RemoteTestNG.main(RemoteTestNG.java:91)
]]>
            </full-stacktrace>
          </exception> <!-- java.lang.Throwable -->
          <reporter-output>
          </reporter-output>
        </test-method> <!-- Test4 -->
      </class> <!-- Listener.TestClass -->
    </test> <!-- Test -->
  </suite> <!-- Suite -->
</testng-results>
